{
  "comments": [
    {
      "unresolved": true,
      "key": {
        "uuid": "eb54bfa6_3a94b7bc",
        "filename": "add_led_action.cpp",
        "patchSetId": 4
      },
      "lineNbr": 20,
      "author": {
        "id": 1000000
      },
      "writtenOn": "2022-10-24T18:05:20Z",
      "side": 1,
      "message": "Throw std::invalid_argument?",
      "revId": "ab6dbe0688df1f319fe5ed34228917ac00214ffa",
      "serverId": "adbd0a64-1f21-4d83-b585-671fe73cb6e4"
    },
    {
      "unresolved": true,
      "key": {
        "uuid": "ebfb2210_e056d237",
        "filename": "add_led_action.cpp",
        "patchSetId": 4
      },
      "lineNbr": 42,
      "author": {
        "id": 1000000
      },
      "writtenOn": "2022-10-24T18:05:20Z",
      "side": 1,
      "message": "I don\u0027t see the reason to use \u0027exit\u0027 here.  There isn\u0027t much value in having caught any exception.  Let it go up the stack and the application crash.  Calling \u0027exit\u0027 directly doesn\u0027t call destructors and really shouldn\u0027t be used much in C++ code.",
      "revId": "ab6dbe0688df1f319fe5ed34228917ac00214ffa",
      "serverId": "adbd0a64-1f21-4d83-b585-671fe73cb6e4"
    }
  ]
}